Workbook

Sheet Painel
A1: ⚙️ PAINEL DE CONTROLE
B3: Data de referência (HOJE)
B4: 46203
B7: Como funciona: 1. Clique na célula da data acima e escolha o dia na lista suspensa. 2. Adicione novas linhas no final da aba "Log Diário" com a data correspondente. 3. Os dashboards de cada inspetor se atualizam automaticamente. ✅ Nunca é preciso criar novas colunas — basta acrescentar linhas no Log. 📌 Novas datas aparecem automaticamente na lista ao serem adicionadas no Log.

Sheet Painel Geral
A1: 📋 PAINEL GERAL — INSPEÇÃO DE QUALIDADE
A2: =" 📅 Referência: "&TEXT(Painel!$B$4,"DD/MM/YYYY")&" | Total de atividades do dia: "&COUNTIF('Log Diário'!$A$2:$A$154,Painel!$B$4) -> 📅 Referência: 30/06/YYYY | Total de atividades do dia: 15
B4: 👤 Rogério Matos | I4: 👤 Marcos Antonio
B5: Elétrica | I5: Preservação
B6: ATIVIDADES HOJE | D6: ⚠️ PENDÊNCIAS | F6: ✅ OK | I6: ATIVIDADES HOJE | K6: ⚠️ PENDÊNCIAS | M6: ✅ OK
B7: =COUNTIFS('Log Diário'!$B$2:$B$154,"Rogério Matos",'Log Diário'!$A$2:$A$154,Painel!$B$4) -> 3 | D7: =COUNTIFS('Log Diário'!$B$2:$B$154,"Rogério Matos",'Log Diário'!$A$2:$A$154,Painel!$B$4,'Log Diário'!$I$2:$I$154,"Reprovado")+COUNTIFS('Log Diário'!$B$2:$B$154,"Rogério Matos",'Log Diário'!$A$2:$A$154,Painel!$B$4,'Log Diário'!$I$2:$I$154,"Pendência")+COUNTIFS('Log Diário'!$B$2:$B$154,"Rogério Matos",'Log Diário'!$A$2:$A$154,Painel!$B$4,'Log Diário'!$I$2:$I$154,"Não finalizado")+COUNTIFS('Log Diário'!$B$2:$B$154,"Rogério Matos",'Log Diário'!$A$2:$A$154,Painel!$B$4,'Log Diário'!$I$2:$I$154,"Reprovado parcial") -> 0 | F7: =COUNTIFS('Log Diário'!$B$2:$B$154,"Rogério Matos",'Log Diário'!$A$2:$A$154,Painel!$B$4,'Log Diário'!$I$2:$I$154,"Inspecionado OK")+COUNTIFS('Log Diário'!$B$2:$B$154,"Rogério Matos",'Log Diário'!$A$2:$A$154,Painel!$B$4,'Log Diário'!$I$2:$I$154,"Finalizado") -> 0 | I7: =COUNTIFS('Log Diário'!$B$2:$B$154,"Marcos Antonio",'Log Diário'!$A$2:$A$154,Painel!$B$4) -> 2 | K7: =COUNTIFS('Log Diário'!$B$2:$B$154,"Marcos Antonio",'Log Diário'!$A$2:$A$154,Painel!$B$4,'Log Diário'!$I$2:$I$154,"Reprovado")+COUNTIFS('Log Diário'!$B$2:$B$154,"Marcos Antonio",'Log Diário'!$A$2:$A$154,Painel!$B$4,'Log Diário'!$I$2:$I$154,"Pendência")+COUNTIFS('Log Diário'!$B$2:$B$154,"Marcos Antonio",'Log Diário'!$A$2:$A$154,Painel!$B$4,'Log Diário'!$I$2:$I$154,"Não finalizado")+COUNTIFS('Log Diário'!$B$2:$B$154,"Marcos Antonio",'Log Diário'!$A$2:$A$154,Painel!$B$4,'Log Diário'!$I$2:$I$154,"Reprovado parcial") -> 0 | M7: =COUNTIFS('Log Diário'!$B$2:$B$154,"Marcos Antonio",'Log Diário'!$A$2:$A$154,Painel!$B$4,'Log Diário'!$I$2:$I$154,"Inspecionado OK")+COUNTIFS('Log Diário'!$B$2:$B$154,"Marcos Antonio",'Log Diário'!$A$2:$A$154,Painel!$B$4,'Log Diário'!$I$2:$I$154,"Finalizado") -> 0
B9: =IF(COUNTIFS('Log Diário'!$B$2:$B$154,"Rogério Matos",'Log Diário'!$A$2:$A$154,Painel!$B$4,'Log Diário'!$I$2:$I$154,"Reprovado")+COUNTIFS('Log Diário'!$B$2:$B$154,"Rogério Matos",'Log Diário'!$A$2:$A$154,Painel!$B$4,'Log Diário'!$I$2:$I$154,"Pendência")+COUNTIFS('Log Diário'!$B$2:$B$154,"Rogério Matos",'Log Diário'!$A$2:$A$154,Painel!$B$4,'Log Diário'!$I$2:$I$154,"Não finalizado")+COUNTIFS('Log Diário'!$B$2:$B$154,"Rogério Matos",'Log Diário'!$A$2:$A$154,Painel!$B$4,'Log Diário'!$I$2:$I$154,"Reprovado parcial")>0,"⚠️ POSSÍVEL ASSUNTO CHECK-IN — VERIFICAR","✅ Sem pendências hoje") -> ✅ Sem pendências hoje | I9: =IF(COUNTIFS('Log Diário'!$B$2:$B$154,"Marcos Antonio",'Log Diário'!$A$2:$A$154,Painel!$B$4,'Log Diário'!$I$2:$I$154,"Reprovado")+COUNTIFS('Log Diário'!$B$2:$B$154,"Marcos Antonio",'Log Diário'!$A$2:$A$154,Painel!$B$4,'Log Diário'!$I$2:$I$154,"Pendência")+COUNTIFS('Log Diário'!$B$2:$B$154,"Marcos Antonio",'Log Diário'!$A$2:$A$154,Painel!$B$4,'Log Diário'!$I$2:$I$154,"Não finalizado")+COUNTIFS('Log Diário'!$B$2:$B$154,"Marcos Antonio",'Log Diário'!$A$2:$A$154,Painel!$B$4,'Log Diário'!$I$2:$I$154,"Reprovado parcial")>0,"⚠️ POSSÍVEL ASSUNTO CHECK-IN — VERIFICAR","✅ Sem pendências hoje") -> ✅ Sem pendências hoje
B11: 👤 Rafael Vieira | I11: 👤 Edigar Barreto
B12: Eletromecânica | I12: Solda/LP/Eletromec.
B13: ATIVIDADES HOJE | D13: ⚠️ PENDÊNCIAS | F13: ✅ OK | I13: ATIVIDADES HOJE | K13: ⚠️ PENDÊNCIAS | M13: ✅ OK
B14: =COUNTIFS('Log Diário'!$B$2:$B$154,"Rafael Vieira",'Log Diário'!$A$2:$A$154,Painel!$B$4) -> 1 | D14: =COUNTIFS('Log Diário'!$B$2:$B$154,"Rafael Vieira",'Log Diário'!$A$2:$A$154,Painel!$B$4,'Log Diário'!$I$2:$I$154,"Reprovado")+COUNTIFS('Log Diário'!$B$2:$B$154,"Rafael Vieira",'Log Diário'!$A$2:$A$154,Painel!$B$4,'Log Diário'!$I$2:$I$154,"Pendência")+COUNTIFS('Log Diário'!$B$2:$B$154,"Rafael Vieira",'Log Diário'!$A$2:$A$154,Painel!$B$4,'Log Diário'!$I$2:$I$154,"Não finalizado")+COUNTIFS('Log Diário'!$B$2:$B$154,"Rafael Vieira",'Log Diário'!$A$2:$A$154,Painel!$B$4,'Log Diário'!$I$2:$I$154,"Reprovado parcial") -> 0 | F14: =COUNTIFS('Log Diário'!$B$2:$B$154,"Rafael Vieira",'Log Diário'!$A$2:$A$154,Painel!$B$4,'Log Diário'!$I$2:$I$154,"Inspecionado OK")+COUNTIFS('Log Diário'!$B$2:$B$154,"Rafael Vieira",'Log Diário'!$A$2:$A$154,Painel!$B$4,'Log Diário'!$I$2:$I$154,"Finalizado") -> 0 | I14: =COUNTIFS('Log Diário'!$B$2:$B$154,"Edigar Barreto",'Log Diário'!$A$2:$A$154,Painel!$B$4) -> 1 | K14: =COUNTIFS('Log Diário'!$B$2:$B$154,"Edigar Barreto",'Log Diário'!$A$2:$A$154,Painel!$B$4,'Log Diário'!$I$2:$I$154,"Reprovado")+COUNTIFS('Log Diário'!$B$2:$B$154,"Edigar Barreto",'Log Diário'!$A$2:$A$154,Painel!$B$4,'Log Diário'!$I$2:$I$154,"Pendência")+COUNTIFS('Log Diário'!$B$2:$B$154,"Edigar Barreto",'Log Diário'!$A$2:$A$154,Painel!$B$4,'Log Diário'!$I$2:$I$154,"Não finalizado")+COUNTIFS('Log Diário'!$B$2:$B$154,"Edigar Barreto",'Log Diário'!$A$2:$A$154,Painel!$B$4,'Log Diário'!$I$2:$I$154,"Reprovado parcial") -> 0 | M14: =COUNTIFS('Log Diário'!$B$2:$B$154,"Edigar Barreto",'Log Diário'!$A$2:$A$154,Painel!$B$4,'Log Diário'!$I$2:$I$154,"Inspecionado OK")+COUNTIFS('Log Diário'!$B$2:$B$154,"Edigar Barreto",'Log Diário'!$A$2:$A$154,Painel!$B$4,'Log Diário'!$I$2:$I$154,"Finalizado") -> 0
B16: =IF(COUNTIFS('Log Diário'!$B$2:$B$154,"Rafael Vieira",'Log Diário'!$A$2:$A$154,Painel!$B$4,'Log Diário'!$I$2:$I$154,"Reprovado")+COUNTIFS('Log Diário'!$B$2:$B$154,"Rafael Vieira",'Log Diário'!$A$2:$A$154,Painel!$B$4,'Log Diário'!$I$2:$I$154,"Pendência")+COUNTIFS('Log Diário'!$B$2:$B$154,"Rafael Vieira",'Log Diário'!$A$2:$A$154,Painel!$B$4,'Log Diário'!$I$2:$I$154,"Não finalizado")+COUNTIFS('Log Diário'!$B$2:$B$154,"Rafael Vieira",'Log Diário'!$A$2:$A$154,Painel!$B$4,'Log Diário'!$I$2:$I$154,"Reprovado parcial")>0,"⚠️ POSSÍVEL ASSUNTO CHECK-IN — VERIFICAR","✅ Sem pendências hoje") -> ✅ Sem pendências hoje | I16: =IF(COUNTIFS('Log Diário'!$B$2:$B$154,"Edigar Barreto",'Log Diário'!$A$2:$A$154,Painel!$B$4,'Log Diário'!$I$2:$I$154,"Reprovado")+COUNTIFS('Log Diário'!$B$2:$B$154,"Edigar Barreto",'Log Diário'!$A$2:$A$154,Painel!$B$4,'Log Diário'!$I$2:$I$154,"Pendência")+COUNTIFS('Log Diário'!$B$2:$B$154,"Edigar Barreto",'Log Diário'!$A$2:$A$154,Painel!$B$4,'Log Diário'!$I$2:$I$154,"Não finalizado")+COUNTIFS('Log Diário'!$B$2:$B$154,"Edigar Barreto",'Log Diário'!$A$2:$A$154,Painel!$B$4,'Log Diário'!$I$2:$I$154,"Reprovado parcial")>0,"⚠️ POSSÍVEL ASSUNTO CHECK-IN — VERIFICAR","✅ Sem pendências hoje") -> ✅ Sem pendências hoje
B18: 👤 Charles Johnson | I18: 👤 Daniel Henrique
B19: Recebimento | I19: Solda/LP/Eletromec.
B20: ATIVIDADES HOJE | D20: ⚠️ PENDÊNCIAS | F20: ✅ OK | I20: ATIVIDADES HOJE | K20: ⚠️ PENDÊNCIAS | M20: ✅ OK
B21: =COUNTIFS('Log Diário'!$B$2:$B$154,"Charles Johnson",'Log Diário'!$A$2:$A$154,Painel!$B$4) -> 0 | D21: =COUNTIFS('Log Diário'!$B$2:$B$154,"Charles Johnson",'Log Diário'!$A$2:$A$154,Painel!$B$4,'Log Diário'!$I$2:$I$154,"Reprovado")+COUNTIFS('Log Diário'!$B$2:$B$154,"Charles Johnson",'Log Diário'!$A$2:$A$154,Painel!$B$4,'Log Diário'!$I$2:$I$154,"Pendência")+COUNTIFS('Log Diário'!$B$2:$B$154,"Charles Johnson",'Log Diário'!$A$2:$A$154,Painel!$B$4,'Log Diário'!$I$2:$I$154,"Não finalizado")+COUNTIFS('Log Diário'!$B$2:$B$154,"Charles Johnson",'Log Diário'!$A$2:$A$154,Painel!$B$4,'Log Diário'!$I$2:$I$154,"Reprovado parcial") -> 0 | F21: =COUNTIFS('Log Diário'!$B$2:$B$154,"Charles Johnson",'Log Diário'!$A$2:$A$154,Painel!$B$4,'Log Diário'!$I$2:$I$154,"Inspecionado OK")+COUNTIFS('Log Diário'!$B$2:$B$154,"Charles Johnson",'Log Diário'!$A$2:$A$154,Painel!$B$4,'Log Diário'!$I$2:$I$154,"Finalizado") -> 0 | I21: =COUNTIFS('Log Diário'!$B$2:$B$154,"Daniel Henrique",'Log Diário'!$A$2:$A$154,Painel!$B$4) -> 8 | K21: =COUNTIFS('Log Diário'!$B$2:$B$154,"Daniel Henrique",'Log Diário'!$A$2:$A$154,Painel!$B$4,'Log Diário'!$I$2:$I$154,"Reprovado")+COUNTIFS('Log Diário'!$B$2:$B$154,"Daniel Henrique",'Log Diário'!$A$2:$A$154,Painel!$B$4,'Log Diário'!$I$2:$I$154,"Pendência")+COUNTIFS('Log Diário'!$B$2:$B$154,"Daniel Henrique",'Log Diário'!$A$2:$A$154,Painel!$B$4,'Log Diário'!$I$2:$I$154,"Não finalizado")+COUNTIFS('Log Diário'!$B$2:$B$154,"Daniel Henrique",'Log Diário'!$A$2:$A$154,Painel!$B$4,'Log Diário'!$I$2:$I$154,"Reprovado parcial") -> 0 | M21: =COUNTIFS('Log Diário'!$B$2:$B$154,"Daniel Henrique",'Log Diário'!$A$2:$A$154,Painel!$B$4,'Log Diário'!$I$2:$I$154,"Inspecionado OK")+COUNTIFS('Log Diário'!$B$2:$B$154,"Daniel Henrique",'Log Diário'!$A$2:$A$154,Painel!$B$4,'Log Diário'!$I$2:$I$154,"Finalizado") -> 3
B23: =IF(COUNTIFS('Log Diário'!$B$2:$B$154,"Charles Johnson",'Log Diário'!$A$2:$A$154,Painel!$B$4,'Log Diário'!$I$2:$I$154,"Reprovado")+COUNTIFS('Log Diário'!$B$2:$B$154,"Charles Johnson",'Log Diário'!$A$2:$A$154,Painel!$B$4,'Log Diário'!$I$2:$I$154,"Pendência")+COUNTIFS('Log Diário'!$B$2:$B$154,"Charles Johnson",'Log Diário'!$A$2:$A$154,Painel!$B$4,'Log Diário'!$I$2:$I$154,"Não finalizado")+COUNTIFS('Log Diário'!$B$2:$B$154,"Charles Johnson",'Log Diário'!$A$2:$A$154,Painel!$B$4,'Log Diário'!$I$2:$I$154,"Reprovado parcial")>0,"⚠️ POSSÍVEL ASSUNTO CHECK-IN — VERIFICAR","✅ Sem pendências hoje") -> ✅ Sem pendências hoje | I23: =IF(COUNTIFS('Log Diário'!$B$2:$B$154,"Daniel Henrique",'Log Diário'!$A$2:$A$154,Painel!$B$4,'Log Diário'!$I$2:$I$154,"Reprovado")+COUNTIFS('Log Diário'!$B$2:$B$154,"Daniel Henrique",'Log Diário'!$A$2:$A$154,Painel!$B$4,'Log Diário'!$I$2:$I$154,"Pendência")+COUNTIFS('Log Diário'!$B$2:$B$154,"Daniel Henrique",'Log Diário'!$A$2:$A$154,Painel!$B$4,'Log Diário'!$I$2:$I$154,"Não finalizado")+COUNTIFS('Log Diário'!$B$2:$B$154,"Daniel Henrique",'Log Diário'!$A$2:$A$154,Painel!$B$4,'Log Diário'!$I$2:$I$154,"Reprovado parcial")>0,"⚠️ POSSÍVEL ASSUNTO CHECK-IN — VERIFICAR","✅ Sem pendências hoje") -> ✅ Sem pendências hoje
B25: 👤 Renan
B26: Eletromecânica
B27: ATIVIDADES HOJE | D27: ⚠️ PENDÊNCIAS | F27: ✅ OK
B28: =COUNTIFS('Log Diário'!$B$2:$B$154,"Renan",'Log Diário'!$A$2:$A$154,Painel!$B$4) -> 0 | D28: =COUNTIFS('Log Diário'!$B$2:$B$154,"Renan",'Log Diário'!$A$2:$A$154,Painel!$B$4,'Log Diário'!$I$2:$I$154,"Reprovado")+COUNTIFS('Log Diário'!$B$2:$B$154,"Renan",'Log Diário'!$A$2:$A$154,Painel!$B$4,'Log Diário'!$I$2:$I$154,"Pendência")+COUNTIFS('Log Diário'!$B$2:$B$154,"Renan",'Log Diário'!$A$2:$A$154,Painel!$B$4,'Log Diário'!$I$2:$I$154,"Não finalizado")+COUNTIFS('Log Diário'!$B$2:$B$154,"Renan",'Log Diário'!$A$2:$A$154,Painel!$B$4,'Log Diário'!$I$2:$I$154,"Reprovado parcial") -> 0 | F28: =COUNTIFS('Log Diário'!$B$2:$B$154,"Renan",'Log Diário'!$A$2:$A$154,Painel!$B$4,'Log Diário'!$I$2:$I$154,"Inspecionado OK")+COUNTIFS('Log Diário'!$B$2:$B$154,"Renan",'Log Diário'!$A$2:$A$154,Painel!$B$4,'Log Diário'!$I$2:$I$154,"Finalizado") -> 0
B30: =IF(COUNTIFS('Log Diário'!$B$2:$B$154,"Renan",'Log Diário'!$A$2:$A$154,Painel!$B$4,'Log Diário'!$I$2:$I$154,"Reprovado")+COUNTIFS('Log Diário'!$B$2:$B$154,"Renan",'Log Diário'!$A$2:$A$154,Painel!$B$4,'Log Diário'!$I$2:$I$154,"Pendência")+COUNTIFS('Log Diário'!$B$2:$B$154,"Renan",'Log Diário'!$A$2:$A$154,Painel!$B$4,'Log Diário'!$I$2:$I$154,"Não finalizado")+COUNTIFS('Log Diário'!$B$2:$B$154,"Renan",'Log Diário'!$A$2:$A$154,Painel!$B$4,'Log Diário'!$I$2:$I$154,"Reprovado parcial")>0,"⚠️ POSSÍVEL ASSUNTO CHECK-IN — VERIFICAR","✅ Sem pendências hoje") -> ✅ Sem pendências hoje
A33: ="📋 ATIVIDADES DO DIA — "&TEXT(Painel!$B$4,"DD/MM/YYYY") -> 📋 ATIVIDADES DO DIA — 30/06/YYYY
B34: INSPETOR | D34: DISC. | E34: ÁREA | F34: SUPERVISOR | G34: ATIVIDADE | L34: STATUS | M34: ⚠️
B35: Edigar Barreto | D35: ADM | E35: CWA-13/14 / Platô 9A | F35: N/A | G35: Levantamento e baixa de pendências no ControlStru | L35: N/A
B36: Rafael Vieira | D36: MEC | E36: CWA-14 / Prédio Sul (CF-09 e CF-11) | F36: Raimundo | G36: Conferência de torque — Coluna de Flotação 09 e 11 | L36: Inspecionado
B37: Daniel Henrique | D37: SOLDA | E37: Platô 2A | F37: Gilberto | G37: Ajuste da junta horizontal da virola 02 com 03 da caixa CX-01 | L37: Em andamento
B38: Daniel Henrique | D38: SOLDA | E38: Platô 2A | F38: Gilberto | G38: Ajuste da junta horizontal da virola 01 com virola 02 da caixa CX-02 | L38: Inspecionado OK
B39: Daniel Henrique | D39: SOLDA | E39: Platô 2A | F39: Gilberto | G39: Montagem da virola 03 da caixa CX-02 | L39: Em andamento
B40: Daniel Henrique | D40: SOLDA | E40: Platô 2A | F40: Gilberto | G40: Ajuste das juntas verticais da calha CX-01 — em fase de soldagem | L40: Inspecionado OK | M40: ⚠️
B41: Daniel Henrique | D41: SOLDA | E41: Platô 2A | F41: Gilberto | G41: Ajuste das juntas verticais da calha da caixa CX-02 | L41: Em andamento
B42: Daniel Henrique | D42: TUB | E42: Platô 2A | F42: Gilberto | G42: Montagem da tubulação de spray da calha da coluna de Flotação FC-20 | L42: Em andamento
B43: Daniel Henrique | D43: TUB | E43: Platô 2A | F43: Gilberto | G43: Pré-montagem da tubulação de alimentação da Coluna de Flotação FC-17 e FC-18 | L43: Em andamento
B44: Daniel Henrique | D44: MEC | E44: Platô 2A | F44: Gilberto | G44: Montagem e torque nos parafusos do distribuidor na Coluna de Flotação FC-20 | L44: Inspecionado OK
B45: Rogério Matos | D45: ELE | E45: CWA-13/14 / Platô 9A | F45: Renato | G45: Montagem infraestrutura iluminação CWA-13/14 | L45: Em andamento
B46: Rogério Matos | D46: ELE | E46: CWA-13/14 / Platô 9A | F46: Renato | G46: Fabricação (suportes leito de cabos, eletrodutos e leito de cabos) | L46: Em andamento
B47: Rogério Matos | D47: ELE | E47: CWA-20 / Platô 11 | F47: Renato | G47: Montagem suportes leito de cabos | L47: Em andamento
B48: Marcos Antonio | D48: MAT | E48: Platô 16 | F48: Arlem | G48: Recebimento de parafusos | L48: Encerrado
B49: Marcos Antonio | D49: MAT | E49: Platô 9A | F49: Leonildo | G49: Preservação — Colunas de Flotação | L49: Em andamento
A51: Total de atividades: 15 | Data: 30/06/2026

Sheet Log Diário
A1: DATA | B1: INSPETOR | C1: DISC. | D1: ÁREA | E1: SUPERVISOR | F1: ATIVIDADE | G1: UNID. | H1: QTD | I1: STATUS | J1: ALERTA | K1: OBSERVAÇÃO
A2: 46188 | B2: Rogério Matos | C2: ELE | D2: CWA-13/14 | E2: Renato Santos/GLENISON | F2: Montagem infraestrutura de iluminação | G2: - | H2: - | I2: Em andamento | K2: Atividade reportada em 15/06/2026 — Relatório diário de montagem
A3: 46188 | B3: Rogério Matos | C3: ELE | D3: CWA-13/14 | E3: GLENISON | F3: Fabricação (suportes de leito de cabos, eletrodutos e leito de cabos) | G3: - | H3: - | I3: Em andamento | K3: Atividade reportada em 15/06/2026 — Relatório diário de montagem
A4: 46188 | B4: Rogério Matos | C4: ELE | D4: CWA-017 | E4: Renato Santos | F4: Montagem infraestrutura (suportes, leito de cabos) — porão de cabos | G4: - | H4: - | I4: Em andamento | K4: Atividade reportada em 15/06/2026 — Relatório diário de montagem
A5: 46188 | B5: Rafael Vieira | C5: MEC | D5: CWA-14 | E5: - | F5: Acompanhamento de montagem e aperto dos parafusos da Coluna de Flotação 01 e 02 | G5: - | H5: - | I5: Acompanhamento | K5: Atividade reportada em 15/06/2026 — Relatório diário de montagem
A6: 46188 | B6: Edigar Barreto | C6: TUB | D6: CWA-13 | E6: Rosino/Oliveira Neto | F6: Acompanhamento de Montagem e ajustes de suportes de tubulação | G6: t | H6: 0.84 | I6: Acompanhamento
A7: 46188 | B7: Edigar Barreto | C7: MEC | D7: CWA-11 | E7: Raimundo Pantoja | F7: Acompanhamento de montagem e ajuste TQ-01 | G7: - | H7: - | I7: Acompanhamento | K7: Atividade reportada em 15/06/2026 — Relatório diário de montagem
A8: 46188 | B8: Edigar Barreto | C8: SOLDA | D8: Prédio Norte | E8: - | F8: Acompanhamento de soldagem de chapas de piso EL.789.706 | G8: - | H8: - | I8: Acompanhamento | K8: Atividade reportada em 15/06/2026 — Relatório diário de montagem
A9: 46188 | B9: Edigar Barreto | C9: ADM | D9: - | E9: - | F9: Emissão de relatórios | G9: - | H9: - | I9: Acompanhamento | K9: Atividade reportada em 15/06/2026 — Relatório diário de montagem
A10: 46188 | B10: Daniel Henrique | C10: SOLDA | D10: Platô 2A | E10: - | F10: Acabamento das soldas verticais da virola 02 CX-02 | G10: - | H10: - | I10: Acompanhamento
A11: 46188 | B11: Daniel Henrique | C11: SOLDA | D11: Platô 2A | E11: - | F11: Soldagem das verticais da virola 03 CX-02 | G11: - | H11: - | I11: Acompanhamento
A12: 46188 | B12: Daniel Henrique | C12: SOLDA | D12: Platô 2A | E12: - | F12: Início da soldagem das juntas de emenda da chapa de fundo CX-02 | G12: - | H12: - | I12: Acompanhamento
A13: 46188 | B13: Charles Johnson | C13: MAT | D13: - | E13: Arlem | F13: Recebimento de materiais, pré moldados. | G13: - | H13: - | I13: Inspecionado OK | K13: Atividade reportada em 15/06/2026 — Relatório diário
A14: 46189 | B14: Edigar Barreto | C14: TUB | D14: CWA-13 | E14: Rosino/Oliveira Neto | F14: Continuação - Montagem e ajustes de suportes de tubulação | G14: t | H14: 0.84 | I14: Inspecionado OK
A15: 46189 | B15: Rogério Matos | C15: ELE | D15: CWA-13/14 | E15: Renato Santos | F15: Continuação montagem de leito CWA-13/14 | G15: m | H15: - | I15: Em andamento
A16: 46189 | B16: Renan | C16: MEC | D16: CWA-20 | E16: Thiago | F16: Montagem telhado | G16: - | H16: - | I16: Acompanhamento | K16: Atividade reportada em 16/06/2026 — Relatório diário
A17: 46189 | B17: Renan | C17: MEC | D17: CWA-20 | E17: Thiago | F17: Montagem escada | G17: - | H17: - | I17: Acompanhamento | K17: Atividade reportada em 16/06/2026 — Relatório diário
A18: 46189 | B18: Renan | C18: MEC | D18: CWA-14 | E18: Thiago | F18: Montagem plataforma | G18: - | H18: - | I18: Acompanhamento | K18: Atividade reportada em 16/06/2026 — Relatório diário
A19: 46189 | B19: Rogério Matos | C19: ELE | D19: CWA-13/14 | E19: Renato | F19: Montagem infraestrutura iluminação | G19: - | H19: - | I19: Em andamento
A20: 46189 | B20: Rogério Matos | C20: ELE | D20: CWA-13/14 | E20: Renato | F20: Fabricação (suportes leito de cabos, eletrodutos e leito de cabos) | G20: - | H20: - | I20: Em andamento
A21: 46189 | B21: Rogério Matos | C21: ELE | D21: CWA-17 | E21: Renato | F21: Montagem infraestrutura (suportes, leito de cabos) porão de cabos | G21: - | H21: - | I21: Em andamento
A22: 46189 | B22: Rafael Vieira | C22: MEC | D22: CWA-14 | E22: - | F22: Acompanhamento de torque das Colunas de flotação 01, 02 e 03 | G22: - | H22: - | I22: Acompanhamento
A23: 46189 | B23: Rafael Vieira | C23: MEC | D23: CWA-13 | E23: - | F23: Acompanhamento de torque das vigas 857B e 1685A — última elevação | G23: - | H23: - | I23: Acompanhamento
A24: 46189 | B24: Daniel Henrique | C24: SOLDA | D24: Platô 13A | E24: Gilberto | F24: Ensaio Visual e LP nas soldas das chapas das Bases da Casa dos Compressores. Iniciado pré-montagem das estruturas da plataforma de escada de acesso às caixas. | G24: - | H24: - | I24: Reprovado | J24: ⚠️ | K24: Reprovado — em fase de reparo dos defeitos apresentados no LP. Encaminhado fotos no grupo de fechamento de QTO para encerrar QTO-0043. Solicitado o cadastramento no Controlstru.
A25: 46189 | B25: Edigar Barreto | C25: LP | D25: - | E25: - | F25: Realização de EVS e LP em nervuras modificadas conforme CTE-74 | G25: - | H25: - | I25: Em andamento
A26: 46189 | B26: Marcos Antonio | C26: MAT | D26: Platô 16 | E26: Arlen | F26: Recebimento: 20 spools em inox / Colunas de Flotação + elementos de ligação (parafusos) | G26: - | H26: - | I26: Finalizado
A27: 46189 | B27: Marcos Antonio | C27: MAT | D27: Platô 9A | E27: Leonildo | F27: Preservação — Amostrador 0415-AM-11 | G27: - | H27: - | I27: Finalizado
A28: 46189 | B28: Charles Johnson | C28: MAT | D28: - | E28: Arlem | F28: Recebimento de materiais — 8 spools tubulação revestida | G28: - | H28: - | I28: Inspecionado OK | K28: Recebimento com observação: sem certificado. RM parcial ainda aberta.
A29: 46189 | B29: Charles Johnson | C29: TUB | D29: Platô 13 | E29: - | F29: Recebimento de conexões de tubulação | G29: - | H29: - | I29: Em andamento
A30: 46189 | B30: Renan | C30: MEC | D30: CWA-14 | E30: Thiago | F30: Montagem estrutura plataforma | G30: - | H30: - | I30: Acompanhamento
A31: 46189 | B31: Renan | C31: MEC | D31: CWA-13 | E31: Thiago | F31: Montagem estrutura plataforma | G31: - | H31: - | I31: Acompanhamento
A32: 46190 | B32: Rogério Matos | C32: ELE | D32: CWA-13/14 | E32: Renato | F32: Montagem infraestrutura iluminação CWA-13/14 | G32: - | H32: - | I32: Em andamento
A33: 46190 | B33: Rogério Matos | C33: ELE | D33: CWA-13/14 | E33: Renato | F33: Fabricação (suportes leito de cabos, eletrodutos e leito de cabos) | G33: - | H33: - | I33: Em andamento
A34: 46190 | B34: Rogério Matos | C34: ELE | D34: CWA-17 | E34: Renato | F34: Montagem infraestrutura (suportes, leito de cabos) porão de cabos | G34: - | H34: - | I34: Em andamento
A35: 46190 | B35: Edigar Barreto | C35: LP | D35: CWA-13 | E35: Raimundo | F35: Realização de EVS e LP em nervuras modificadas conforme CTE-74 | G35: - | H35: - | I35: Inspecionado OK
A36: 46190 | B36: Daniel Henrique | C36: SOLDA | D36: Platô 2A | E36: Gilberto | F36: Acompanhamento da preparação dos segmentos da calha da caixa CX-01 e CX-02 para montagem | G36: - | H36: - | I36: Reprovado | J36: ⚠️ | K36: ⚠️ ASSUNTO CHECK-IN: Emitido QTO para CX-01 devido a problema no bisel da chapa 210B. Progen deu disposição para retrabalhar o bisel.
A37: 46190 | B37: Daniel Henrique | C37: SOLDA | D37: Platô 2A | E37: Gilberto | F37: Acompanhamento do ajuste da junta horizontal JH-01 da caixa CX-01 | G37: - | H37: - | I37: Não finalizado | J37: ⚠️ | K37: ⚠️ ASSUNTO CHECK-IN: Verificar situação — status: Não finalizado
A38: 46190 | B38: Daniel Henrique | C38: SOLDA | D38: Platô 2A | E38: Gilberto | F38: Acompanhamento da soldagem das juntas JF-02 e JF-03 | G38: - | H38: - | I38: Não finalizado | J38: ⚠️ | K38: ⚠️ ASSUNTO CHECK-IN: Verificar situação — status: Não finalizado
A39: 46190 | B39: Daniel Henrique | C39: MAT | D39: Platô 2A | E39: Gilberto | F39: Recebimento de consumíveis de solda | G39: - | H39: - | I39: Reprovado parcial | J39: ⚠️ | K39: ⚠️ ASSUNTO CHECK-IN: Não foi apresentado certificado dos arames da Bohler.
A40: 46190 | B40: Marcos Antonio | C40: MAT | D40: Platô 16 | E40: Arlen | F40: Recebimento tubulação e acessórios 8, 10, 12, 14, 16 e 18" (Documentação) | G40: - | H40: - | I40: Em andamento
...

Sheet CWA - Referência
A1: REFERÊNCIA DE CWAs — PROJETO RECLEANER
A2: Total: 63 CWAs cadastradas
A3: ID | B3: DESCRITIVO | C3: Nº CWA | D3: DESCRIÇÃO DO CWA | E3: ESCOPO
A4: 00 | B4: GERAL | C4: AMR-1006916-000-00 | D4: Geral | E4: Escopo Original e Novo Escopo
A5: 01 | B5: TANQUE DE POLPA | C5: AMR-1006916-001-01 | D5: Bombas / Agitadores / Tanques - 0414-BP-07/08/09/10/11; 0414 AG-02; 0414 TQ-02; 0416-BP-07/08/09/10/11; 0416 AG-02; 0416 TQ-02 | E5: Novo escopo
A6: 02 | B6: PIPE RACK TANQUE DE POLPA - TRECHO 6 | C6: AMR-1006916-002-02 | D6: Pipe rack entre os tanques de polpa 0414/0416-TQ-02 e os prédios remoagem e moagem secundária - Trecho 6 | E6: Novo escopo
A7: 03 | B7: SUBESTAÇÃO DA CONCENTRAÇAO 0764-SE-0I - EXISTENTE | C7: AMR-1006916-003-03 | D7: Reforço civil e instalação de novos equipamentos (10 painéis de inversores, 02 painéis de controle de automação) | E7: Novo escopo
A8: 04 | B8: REMOAGEM EXISTENTE | C8: AMR-1006916-004-04 | D8: Esta CWA compreende a substituição 0414-HC-01/02/03/04/05 (cancelada) | E8: Cancelado
A9: 05 | B9: MOAGEM SECUNDÁRIA EXISTENTE | C9: AMR-1006916-005-05 | D9: Esta CWA compreende a substituição 0416-HC-01/02/03/04/05 (cancelada) | E9: Cancelado
A10: 06 | B10: SEGUNDA CLASSIFICAÇÃO - REMOAGEM | C10: AMR-1006916-006-06 | D10: Hidrociclones e Talhas - 0416-HC-06/07/08/09/10 (instalação de novos HC) e 02 talhas | E10: Novo escopo
A11: 07 | B11: SEGUNDA CLASSIFICAÇÃO - MOAGEM SECUNDÁRIA | C11: AMR-1006916-007-07 | D11: Hidrociclones e Talhas - 0416-0414-HC-01/02/03/04/05 (instalação de novos HC) e 02 talhas | E11: Novo escopo
A12: 08 | B12: SISTEMA DE AMOSTRAGEM CONCENTRADO | C12: AMR-1006916-008-08 | D12: Amostradores - 0415-AM-05/06; Caixas 0414-CX-02 / 0416-CX-02 | E12: Novo escopo
A13: 09 | B13: Caixas 0414 & 0416-CX-01 e Tanques 0414 & 0416-TQ-01 | C13: AMR-1006916-009-09 | D13: Caixas e bombas - 0414-CX-01; 0414-BP-06; 0416-CX-01; 0416-BP-06; Tanques e bombas 0414-TQ-01; 0414-BP-01@05; 0416-TQ-01; 0416-BP-01@05 | E13: Novo escopo
A14: 10 | B14: PIRE RACK TRECHO 5 | C14: AMR-1006916-010-10 | D14: Pipe rack para alimentação dos tanques condicionadores (CWA 11) Trecho 5 | E14: Escopo Original
... A66: 62 | B66: ESTAÇÃO DE BOMBEAMENTO | C66: AMR-1006916-58-62 | D66: Estação De Bombeamento | E66: Novo escopo
A68: LEGENDA — ESCOPO
A69: Escopo Original
A70: Novo escopo
A71: Cancelado
A72: Escopo Original e Novo Escopo

Sheet Rogério Matos
C1: ROGÉRIO MATOS
C2: Inspeção de Qualidade — Elétrica
C3: 📅 Data de referência: | M3: =Painel!$B$4 -> 46203
C5: ATIVIDADES HOJE | G5: EM ANDAMENTO/ACOMP. HOJE | K5: PENDÊNCIAS HOJE
C6: =COUNTIFS('Log Diário'!$B$2:$B$699,"Rogério Matos",'Log Diário'!$A$2:$A$699,Painel!$B$4) -> 3 | G6: =COUNTIFS('Log Diário'!$B$2:$B$699,"Rogério Matos",'Log Diário'!$A$2:$A$699,Painel!$B$4,'Log Diário'!$I$2:$I$699,"Em andamento")+COUNTIFS('Log Diário'!$B$2:$B$699,"Rogério Matos",'Log Diário'!$A$2:$A$699,Painel!$B$4,'Log Diário'!$I$2:$I$699,"Acompanhamento") -> 3 | K6: =COUNTIFS('Log Diário'!$B$2:$B$699,"Rogério Matos",'Log Diário'!$A$2:$A$699,Painel!$B$4,'Log Diário'!$I$2:$I$699,"Pendência")+COUNTIFS('Log Diário'!$B$2:$B$699,"Rogério Matos",'Log Diário'!$A$2:$A$699,Painel!$B$4,'Log Diário'!$I$2:$I$699,"Reprovado") -> 0
C10: ="📈 Total de atividades registradas em "&INDEX({"janeiro";"fevereiro";"março";"abril";"maio";"junho";"julho";"agosto";"setembro";"outubro";"novembro";"dezembro"},MONTH(Painel!$B$4))&"/"&YEAR(Painel!$B$4)&": "&COUNTIFS('Log Diário'!$B$2:$B$699,"Rogério Matos",'Log Diário'!$A$2:$A$699,">"&DATE(YEAR(Painel!$B$4),MONTH(Painel!$B$4),1),'Log Diário'!$A$2:$A$699,"<"&DATE(YEAR(Painel!$B$4),MONTH(Painel!$B$4)+1,1))&" atividades" -> 📈 Total de atividades registradas em junho/2026: 18 atividades
H12: 📋 DISCIPLINAS ENVOLVIDAS HOJE
H13: =TRIM(IF(COUNTIFS('Log Diário'!$B$2:$B$699,"Rogério Matos",'Log Diário'!$A$2:$A$699,Painel!$B$4,'Log Diário'!$C$2:$C$699,"ELE")>0,"ELE ","")&IF(COUNTIFS('Log Diário'!$B$2:$B$699,"Rogério Matos",'Log Diário'!$A$2:$A$699,Painel!$B$4,'Log Diário'!$C$2:$C$699,"TUB")>0,"TUB ","")&IF(COUNTIFS('Log Diário'!$B$2:$B$699,"Rogério Matos",'Log Diário'!$A$2:$A$699,Painel!$B$4,'Log Diário'!$C$2:$C$699,"MEC")>0,"MEC ","")&IF(COUNTIFS('Log Diário'!$B$2:$B$699,"Rogério Matos",'Log Diário'!$A$2:$A$699,Painel!$B$4,'Log Diário'!$C$2:$C$699,"SOLDA")>0,"SOLDA ","")&IF(COUNTIFS('Log Diário'!$B$2:$B$699,"Rogério Matos",'Log Diário'!$A$2:$A$699,Painel!$B$4,'Log Diário'!$C$2:$C$699,"AND")>0,"AND ","")&IF(COUNTIFS('Log Diário'!$B$2:$B$699,"Rogério Matos",'Log Diário'!$A$2:$A$699,Painel!$B$4,'Log Diário'!$C$2:$C$699,"ADM")>0,"ADM ","")) -> ELE
H15: 📍 ÁREAS / CWAs EM ACOMPANHAMENTO HOJE
H16: {=IF(RIGHT(IFERROR(INDEX('Log Diário'!$D$2:$D$699,SMALL(IF(('Log Diário'!$B$2:$B$699="Rogério Matos")*('Log Diário'!$A$2:$A$699=Painel!$B$4),ROW('Log Diário'!$A$2:$A$699)-1,""),1))&" | ","")&IFERROR(INDEX('Log Diário'!$D$2:$D$699,SMALL(IF(('Log Diário'!$B$2:$B$699="Rogério Matos")*('Log Diário'!$A$2:$A$699=Painel!$B$4),ROW('Log Diário'!$A$2:$A$699)-1,""),2))&" | ","")&IFERROR(INDEX('Log Diário'!$D$2:$D$699,SMALL(IF(('Log Diário'!$B$2:$B$699="Rogério Matos")*('Log Diário'!$A$2:$A$699=Painel!$B$4),ROW('Log Diário'!$A$2:$A$699)-1,""),3))&" | ","")&IFERROR(INDEX('Log Diário'!$D$2:$D$699,SMALL(IF(('Log Diário'!$B$2:$B$699="Rogério Matos")*('Log Diário'!$A$2:$A$699=Painel!$B$4),ROW('Log Diário'!$A$2:$A$699)-1,""),4))&" | ","")&IFERROR(INDEX('Log Diário'!$D$2:$D$699,SMALL(IF(('Log Diário'!$B$2:$B$699="Rogério Matos")*('Log Diário'!$A$2:$A$699=Painel!$B$4),ROW('Log Diário'!$A$2:$A$699)-1,""),5))&" | ","")&IFERROR(INDEX('Log Diário'!$D$2:$D$699,SMALL(IF(('Log Diário'!$B$2:$B$699="Rogério Matos")*('Log Diário'!$A$2:$A$699=Painel!$B$4),ROW('Log Diário'!$A$2:$A$699)-1,""),6))&" | ",""),7)=" | ",LEFT(IFERROR(INDEX('Log Diário'!$D$2:$D$699,SMALL(IF(('Log Diário'!$B$2:$B$699="Rogério Matos")*('Log Diário'!$A$2:$A$699=Painel!$B$4),ROW('Log Diário'!$A$2:$A$699)-1,""),1))&" | ","")&IFERROR(INDEX('Log Diário'!$D$2:$D$699,SMALL(IF(('Log Diário'!$B$2:$B$699="Rogério Matos")*('Log Diário'!$A$2:$A$699=Painel!$B$4),ROW('Log Diário'!$A$2:$A$699)-1,""),2))&" | ","")&IFERROR(INDEX('Log Diário'!$D$2:$D$699,SMALL(IF(('Log Diário'!$B$2:$B$699="Rogério Matos")*('Log Diário'!$A$2:$A$699=Painel!$B$4),ROW('Log Diário'!$A$2:$A$699)-1,""),3))&" | ","")&IFERROR(INDEX('Log Diário'!$D$2:$D$699,SMALL(IF(('Log Diário'!$B$2:$B$699="Rogério Matos")*('Log Diário'!$A$2:$A$699=Painel!$B$4),ROW('Log Diário'!$A$2:$A$699)-1,""),4))&" | ","")&IFERROR(INDEX('Log Diário'!$D$2:$D$699,SMALL(IF(('Log Diário'!$B$2:$B$699="Rogério Matos")*('Log Diário'!$A$2:$A$699=Painel!$B$4),ROW('Log Diário'!$A$2:$A$699)-1,""),5))&" | ","")&IFERROR(INDEX('Log Diário'!$D$2:$D$699,SMALL(IF(('Log Diário'!$B$2:$B$699="Rogério Matos")*('Log Diário'!$A$2:$A$699=Painel!$B$4),ROW('Log Diário'!$A$2:$A$699)-1,""),6))&" | ",""),LEN(IFERROR(INDEX('Log Diário'!$D$2:$D$699,SMALL(IF(('Log Diário'!$B$2:$B$699="Rogério Matos")*('Log Diário'!$A$2:$A$699=Painel!$B$4),ROW('Log Diário'!$A$2:$A$699)-1,""),1))&" | ","")&IFERROR(INDEX('Log Diário'!$D$2:$D$699,SMALL(IF(('Log Diário'!$B$2:$B$699="Rogério Matos")*('Log Diário'!$A$2:$A$699=Painel!$B$4),ROW('Log Diário'!$A$2:$A$699)-1,""),2))&" | ","")&IFERROR(INDEX('Log Diário'!$D$2:$D$699,SMALL(IF(('Log Diário'!$B$2:$B$699="Rogério Matos")*('Log Diário'!$A$2:$A$699=Painel!$B$4),ROW('Log Diário'!$A$2:$A$699)-1,""),3))&" | ","")&IFERROR(INDEX('Log Diário'!$D$2:$D$699,SMALL(IF(('Log Diário'!$B$2:$B$699="Rogério Matos")*('Log Diário'!$A$2:$A$699=Painel!$B$4),ROW('Log Diário'!$A$2:$A$699)-1,""),4))&" | ","")&IFERROR(INDEX('Log Diário'!$D$2:$D$699,SMALL(IF(('Log Diário'!$B$2:$B$699="Rogério Matos")*('Log Diário'!$A$2:$A$699=Painel!$B$4),ROW('Log Diário'!$A$2:$A$699)-1,""),5))&" | ","")&IFERROR(INDEX('Log Diário'!$D$2:$D$699,SMALL(IF(('Log Diário'!$B$2:$B$699="Rogério Matos")*('Log Diário'!$A$2:$A$699=Painel!$B$4),ROW('Log Diário'!$A$2:$A$699)-1,""),6))&" | ",""))-7),IFERROR(INDEX('Log Diário'!$D$2:$D$699,SMALL(IF(('Log Diário'!$B$2:$B$699="Rogério Matos")*('Log Diário'!$A$2:$A$699=Painel!$B$4),ROW('Log Diário'!$A$2:$A$699)-1,""),1))&" | ","")&IFERROR(INDEX('Log Diário'!$D$2:$D$699,SMALL(IF(('Log Diário'!$B$2:$B$699="Rogério Matos")*('Log Diário'!$A$2:$A$699=Painel!$B$4),ROW('Log Diário'!$A$2:$A$699)-1,""),2))&" | ","")&IFERROR(INDEX('Log Diário'!$D$2:$D$699,SMALL(IF(('Log Diário'!$B$2:$B$699="Rogério Matos")*('Log Diário'!$A$2:$A$699=Painel!$B$4),ROW('Log Diário'!$A$2:$A$699)-1,""),3))&" | ","")&IFERROR(INDEX('Log Diário'!$D$2:$D$699,SMALL(IF(('Log Diário'!$B$2:$B$699="Rogério Matos")*('Log Diário'!$A$2:$A$699=Painel!$B$4),ROW('Log Diário'!$A$2:$A$699)-1,""),4))&" | ","")&IFERROR(INDEX('Log Diário'!$D$2:$D$699,SMALL(IF(('Log Diário'!$B$2:$B$699="Rogério Matos")*('Log Diário'!$A$2:$A$699=Painel!$B$4),ROW('Log Diário'!$A$2:$A$699)-1,""),5))&" | ","")&IFERROR(INDEX('Log Diário'!$D$2:$D$699,SMALL(IF(('Log Diário'!$B$2:$B$699="Rogério Matos")*('Log Diário'!$A$2:$A$699=Painel!$B$4),ROW('Log Diário'!$A$2:$A$699)-1,""),6))&" | ",""))} -> CWA-13/14 / Platô 9A | CWA-13/14 / Platô 9A | CWA-20 / Platô 11
C28: ="🗓️ ATIVIDADES DE HOJE — "&TEXT(Painel!$B$4,"DD/MM/YYYY") -> 🗓️ ATIVIDADES DE HOJE — 30/06/YYYY
C29: DISC. | D29: ÁREA | E29: SUPERVISOR | F29: ATIVIDADE | K29: STATUS | M29: ⚠️ OBSERVAÇÃO / CHECK-IN
C30: {=IFERROR(INDEX('Log Diário'!$C$2:$C$156,SMALL(IF(('Log Diário'!$B$2:$B$156="Rogério Matos")*('Log Diário'!$A$2:$A$156=Painel!$B$4),ROW('Log Diário'!$A$2:$A$156)-1,""),1)),"")} -> ELE | D30: {=IFERROR(INDEX('Log Diário'!$D$2:$D$156,SMALL(IF(('Log Diário'!$B$2:$B$156="Rogério Matos")*('Log Diário'!$A$2:$A$156=Painel!$B$4),ROW('Log Diário'!$A$2:$A$156)-1,""),1)),"")} -> CWA-13/14 / Platô 9A | E30: {=IFERROR(INDEX('Log Diário'!$E$2:$E$156,SMALL(IF(('Log Diário'!$B$2:$B$156="Rogério Matos")*('Log Diário'!$A$2:$A$156=Painel!$B$4),ROW('Log Diário'!$A$2:$A$156)-1,""),1)),"")} -> Renato | F30: {=IFERROR(INDEX('Log Diário'!$F$2:$F$156,SMALL(IF(('Log Diário'!$B$2:$B$156="Rogério Matos")*('Log Diário'!$A$2:$A$156=Painel!$B$4),ROW('Log Diário'!$A$2:$A$156)-1,""),1)),"")} -> Montagem infraestrutura iluminação CWA-13/14 | K30: {=IFERROR(INDEX('Log Diário'!$I$2:$I$156,SMALL(IF(('Log Diário'!$B$2:$B$156="Rogério Matos")*('Log Diário'!$A$2:$A$156=Painel!$B$4),ROW('Log Diário'!$A$2:$A$156)-1,""),1)),"")} -> Em andamento | M30: {=IFERROR(INDEX('Log Diário'!$K$2:$K$156,SMALL(IF(('Log Diário'!$B$2:$B$156="Rogério Matos")*('Log Diário'!$A$2:$A$156=Painel!$B$4),ROW('Log Diário'!$A$2:$A$156)-1,""),1)),"")&""}
C31: {=IFERROR(INDEX('Log Diário'!$C$2:$C$156,SMALL(IF(('Log Diário'!$B$2:$B$156="Rogério Matos")*('Log Diário'!$A$2:$A$156=Painel!$B$4),ROW('Log Diário'!$A$2:$A$156)-1,""),2)),"")} -> ELE | D31: {=IFERROR(INDEX('Log Diário'!$D$2:$D$156,SMALL(IF(('Log Diário'!$B$2:$B$156="Rogério Matos")*('Log Diário'!$A$2:$A$156=Painel!$B$4),ROW('Log Diário'!$A$2:$A$156)-1,""),2)),"")} -> CWA-13/14 / Platô 9A | E31: {=IFERROR(INDEX('Log Diário'!$E$2:$E$156,SMALL(IF(('Log Diário'!$B$2:$B$156="Rogério Matos")*('Log Diário'!$A$2:$A$156=Painel!$B$4),ROW('Log Diário'!$A$2:$A$156)-1,""),2)),"")} -> Renato | F31: {=IFERROR(INDEX('Log Diário'!$F$2:$F$156,SMALL(IF(('Log Diário'!$B$2:$B$156="Rogério Matos")*('Log Diário'!$A$2:$A$156=Painel!$B$4),ROW('Log Diário'!$A$2:$A$156)-1,""),2)),"")} -> Fabricação (suportes leito de cabos, eletrodutos e leito de cabos) | K31: {=IFERROR(INDEX('Log Diário'!$I$2:$I$156,SMALL(IF(('Log Diário'!$B$2:$B$156="Rogério Matos")*('Log Diário'!$A$2:$A$156=Painel!$B$4),ROW('Log Diário'!$A$2:$A$156)-1,""),2)),"")} -> Em andamento | M31: {=IFERROR(INDEX('Log Diário'!$K$2:$K$156,SMALL(IF(('Log Diário'!$B$2:$B$156="Rogério Matos")*('Log Diário'!$A$2:$A$156=Painel!$B$4),ROW('Log Diário'!$A$2:$A$156)-1,""),2)),"")&""}
C32: {=IFERROR(INDEX('Log Diário'!$C$2:$C$156,SMALL(IF(('Log Diário'!$B$2:$B$156="Rogério Matos")*('Log Diário'!$A$2:$A$156=Painel!$B$4),ROW('Log Diário'!$A$2:$A$156)-1,""),3)),"")} -> ELE | D32: {=IFERROR(INDEX('Log Diário'!$D$2:$D$156,SMALL(IF(('Log Diário'!$B$2:$B$156="Rogério Matos")*('Log Diário'!$A$2:$A$156=Painel!$B$4),ROW('Log Diário'!$A$2:$A$156)-1,""),3)),"")} -> CWA-20 / Platô 11 | E32: {=IFERROR(INDEX('Log Diário'!$E$2:$E$156,SMALL(IF(('Log Diário'!$B$2:$B$156="Rogério Matos")*('Log Diário'!$A$2:$A$156=Painel!$B$4),ROW('Log Diário'!$A$2:$A$156)-1,""),3)),"")} -> Renato | F32: {=IFERROR(INDEX('Log Diário'!$F$2:$F$156,SMALL(IF(('Log Diário'!$B$2:$B$156="Rogério Matos")*('Log Diário'!$A$2:$A$156=Painel!$B$4),ROW('Log Diário'!$A$2:$A$156)-1,""),3)),"")} -> Montagem suportes leito de cabos | K32: {=IFERROR(INDEX('Log Diário'!$I$2:$I$156,SMALL(IF(('Log Diário'!$B$2:$B$156="Rogério Matos")*('Log Diário'!$A$2:$A$156=Painel!$B$4),ROW('Log Diário'!$A$2:$A$156)-1,""),3)),"")} -> Em andamento | M32: {=IFERROR(INDEX('Log Diário'!$K$2:$K$156,SMALL(IF(('Log Diário'!$B$2:$B$156="Rogério Matos")*('Log Diário'!$A$2:$A$156=Painel!$B$4),ROW('Log Diário'!$A$2:$A$156)-1,""),3)),"")&""}
C33: {=IFERROR(INDEX('Log Diário'!$C$2:$C$156,SMALL(IF(('Log Diário'!$B$2:$B$156="Rogério Matos")*('Log Diário'!$A$2:$A$156=Painel!$B$4),ROW('Log Diário'!$A$2:$A$156)-1,""),4)),"")} | D33: {=IFERROR(INDEX('Log Diário'!$D$2:$D$156,SMALL(IF(('Log Diário'!$B$2:$B$156="Rogério Matos")*('Log Diário'!$A$2:$A$156=Painel!$B$4),ROW('Log Diário'!$A$2:$A$156)-1,""),4)),"")} | E33: {=IFERROR(INDEX('Log Diário'!$E$2:$E$156,SMALL(IF(('Log Diário'!$B$2:$B$156="Rogério Matos")*('Log Diário'!$A$2:$A$156=Painel!$B$4),ROW('Log Diário'!$A$2:$A$156)-1,""),4)),"")} | F33: {=IFERROR(INDEX('Log Diário'!$F$2:$F$156,SMALL(IF(('Log Diário'!$B$2:$B$156="Rogério Matos")*('Log Diário'!$A$2:$A$156=Painel!$B$4),ROW('Log Diário'!$A$2:$A$156)-1,""),4)),"")} | K33: {=IFERROR(INDEX('Log Diário'!$I$2:$I$156,SMALL(IF(('Log Diário'!$B$2:$B$156="Rogério Matos")*('Log Diário'!$A$2:$A$156=Painel!$B$4),ROW('Log Diário'!$A$2:$A$156)-1,""),4)),"")} | M33: {=IFERROR(INDEX('Log Diário'!$K$2:$K$156,SMALL(IF(('Log Diário'!$B$2:$B$156="Rogério Matos")*('Log Diário'!$A$2:$A$156=Painel!$B$4),ROW('Log Diário'!$A$2:$A$156)-1,""),4)),"")&""}
C34: {=IFERROR(INDEX('Log Diário'!$C$2:$C$156,SMALL(IF(('Log Diário'!$B$2:$B$156="Rogério Matos")*('Log Diário'!$A$2:$A$156=Painel!$B$4),ROW('Log Diário'!$A$2:$A$156)-1,""),5)),"")} | D34: {=IFERROR(INDEX('Log Diário'!$D$2:$D$156,SMALL(IF(('Log Diário'!$B$2:$B$156="Rogério Matos")*('Log Diário'!$A$2:$A$156=Painel!$B$4),ROW('Log Diário'!$A$2:$A$156)-1,""),5)),"")} | E34: {=IFERROR(INDEX('Log Diário'!$E$2:$E$156,SMALL(IF(('Log Diário'!$B$2:$B$156="Rogério Matos")*('Log Diário'!$A$2:$A$156=Painel!$B$4),ROW('Log Diário'!$A$2:$A$156)-1,""),5)),"")} | F34: {=IFERROR(INDEX('Log Diário'!$F$2:$F$156,SMALL(IF(('Log Diário'!$B$2:$B$156="Rogério Matos")*('Log Diário'!$A$2:$A$156=Painel!$B$4),ROW('Log Diário'!$A$2:$A$156)-1,""),5)),"")} | K34: {=IFERROR(INDEX('Log Diário'!$I$2:$I$156,SMALL(IF(('Log Diário'!$B$2:$B$156="Rogério Matos")*('Log Diário'!$A$2:$A$156=Painel!$B$4),ROW('Log Diário'!$A$2:$A$156)-1,""),5)),"")} | M34: {=IFERROR(INDEX('Log Diário'!$K$2:$K$156,SMALL(IF(('Log Diário'!$B$2:$B$156="Rogério Matos")*('Log Diário'!$A$2:$A$156=Painel!$B$4),ROW('Log Diário'!$A$2:$A$156)-1,""),5)),"")&""}
C35: {=IFERROR(INDEX('Log Diário'!$C$2:$C$156,SMALL(IF(('Log Diário'!$B$2:$B$156="Rogério Matos")*('Log Diário'!$A$2:$A$156=Painel!$B$4),ROW('Log Diário'!$A$2:$A$156)-1,""),6)),"")} | D35: {=IFERROR(INDEX('Log Diário'!$D$2:$D$156,SMALL(IF(('Log Diário'!$B$2:$B$156="Rogério Matos")*('Log Diário'!$A$2:$A$156=Painel!$B$4),ROW('Log Diário'!$A$2:$A$156)-1,""),6)),"")} | E35: {=IFERROR(INDEX('Log Diário'!$E$2:$E$156,SMALL(IF(('Log Diário'!$B$2:$B$156="Rogério Matos")*('Log Diário'!$A$2:$A$156=Painel!$B$4),ROW('Log Diário'!$A$2:$A$156)-1,""),6)),"")} | F35: {=IFERROR(INDEX('Log Diário'!$F$2:$F$156,SMALL(IF(('Log Diário'!$B$2:$B$156="Rogério Matos")*('Log Diário'!$A$2:$A$156=Painel!$B$4),ROW('Log Diário'!$A$2:$A$156)-1,""),6)),"")} | K35: {=IFERROR(INDEX('Log Diário'!$I$2:$I$156,SMALL(IF(('Log Diário'!$B$2:$B$156="Rogério Matos")*('Log Diário'!$A$2:$A$156=Painel!$B$4),ROW('Log Diário'!$A$2:$A$156)-1,""),6)),"")} | M35: {=IFERROR(INDEX('Log Diário'!$K$2:$K$156,SMALL(IF(('Log Diário'!$B$2:$B$156="Rogério Matos")*('Log Diário'!$A$2:$A$156=Painel!$B$4),ROW('Log Diário'!$A$2:$A$156)-1,""),6)),"")&""}
C36: {=IFERROR(INDEX('Log Diário'!$C$2:$C$156,SMALL(IF(('Log Diário'!$B$2:$B$156="Rogério Matos")*('Log Diário'!$A$2:$A$156=Painel!$B$4),ROW('Log Diário'!$A$2:$A$156)-1,""),7)),"")} | D36: {=IFERROR(INDEX('Log Diário'!$D$2:$D$156,SMALL(IF(('Log Diário'!$B$2:$B$156="Rogério Matos")*('Log Diário'!$A$2:$A$156=Painel!$B$4),ROW('Log Diário'!$A$2:$A$156)-1,""),7)),"")} | E36: {=IFERROR(INDEX('Log Diário'!$E$2:$E$156,SMALL(IF(('Log Diário'!$B$2:$B$156="Rogério Matos")*('Log Diário'!$A$2:$A$156=Painel!$B$4),ROW('Log Diário'!$A$2:$A$156)-1,""),7)),"")} | F36: {=IFERROR(INDEX('Log Diário'!$F$2:$F$156,SMALL(IF(('Log Diário'!$B$2:$B$156="Rogério Matos")*('Log Diário'!$A$2:$A$156=Painel!$B$4),ROW('Log Diário'!$A$2:$A$156)-1,""),7)),"")} | K36: {=IFERROR(INDEX('Log Diário'!$I$2:$I$156,SMALL(IF(('Log Diário'!$B$2:$B$156="Rogério Matos")*('Log Diário'!$A$2:$A$156=Painel!$B$4),ROW('Log Diário'!$A$2:$A$156)-1,""),7)),"")} | M36: {=IFERROR(INDEX('Log Diário'!$K$2:$K$156,SMALL(IF(('Log Diário'!$B$2:$B$156="Rogério Matos")*('Log Diário'!$A$2:$A$156=Painel!$B$4),ROW('Log Diário'!$A$2:$A$156)-1,""),7)),"")&""}
C37: {=IFERROR(INDEX('Log Diário'!$C$2:$C$156,SMALL(IF(('Log Diário'!$B$2:$B$156="Rogério Matos")*('Log Diário'!$A$2:$A$156=Painel!$B$4),ROW('Log Diário'!$A$2:$A$156)-1,""),8)),"")} | D37: {=IFERROR(INDEX('Log Diário'!$D$2:$D$156,SMALL(IF(('Log Diário'!$B$2:$B$156="Rogério Matos")*('Log Diário'!$A$2:$A$156=Painel!$B$4),ROW('Log Diário'!$A$2:$A$156)-1,""),8)),"")} | E37: {=IFERROR(INDEX('Log Diário'!$E$2:$E$156,SMALL(IF(('Log Diário'!$B$2:$B$156="Rogério Matos")*('Log Diário'!$A$2:$A$156=Painel!$B$4),ROW('Log Diário'!$A$2:$A$156)-1,""),8)),"")} | F37: {=IFERROR(INDEX('Log Diário'!$F$2:$F$156,SMALL(IF(('Log Diário'!$B$2:$B$156="Rogério Matos")*('Log Diário'!$A$2:$A$156=Painel!$B$4),ROW('Log Diário'!$A$2:$A$156)-1,""),8)),"")} | K37: {=IFERROR(INDEX('Log Diário'!$I$2:$I$156,SMALL(IF(('Log Diário'!$B$2:$B$156="Rogério Matos")*('Log Diário'!$A$2:$A$156=Painel!$B$4),ROW('Log Diário'!$A$2:$A$156)-1,""),8)),"")} | M37: {=IFERROR(INDEX('Log Diário'!$K$2:$K$156,SMALL(IF(('Log Diário'!$B$2:$B$156="Rogério Matos")*('Log Diário'!$A$2:$A$156=Painel!$B$4),ROW('Log Diário'!$A$2:$A$156)-1,""),8)),"")&""}
C38: {=IFERROR(INDEX('Log Diário'!$C$2:$C$156,SMALL(IF(('Log Diário'!$B$2:$B$156="Rogério Matos")*('Log Diário'!$A$2:$A$156=Painel!$B$4),ROW('Log Diário'!$A$2:$A$156)-1,""),9)),"")} | D38: {=IFERROR(INDEX('Log Diário'!$D$2:$D$156,SMALL(IF(('Log Diário'!$B$2:$B$156="Rogério Matos")*('Log Diário'!$A$2:$A$156=Painel!$B$4),ROW('Log Diário'!$A$2:$A$156)-1,""),9)),"")} | E38: {=IFERROR(INDEX('Log Diário'!$E$2:$E$156,SMALL(IF(('Log Diário'!$B$2:$B$156="Rogério Matos")*('Log Diário'!$A$2:$A$156=Painel!$B$4),ROW('Log Diário'!$A$2:$A$156)-1,""),9)),"")} | F38: {=IFERROR(INDEX('Log Diário'!$F$2:$F$156,SMALL(IF(('Log Diário'!$B$2:$B$156="Rogério Matos")*('Log Diário'!$A$2:$A$156=Painel!$B$4),ROW('Log Diário'!$A$2:$A$156)-1,""),9)),"")} | K38: {=IFERROR(INDEX('Log Diário'!$I$2:$I$156,SMALL(IF(('Log Diário'!$B$2:$B$156="Rogério Matos")*('Log Diário'!$A$2:$A$156=Painel!$B$4),ROW('Log Diário'!$A$2:$A$156)-1,""),9)),"")} | M38: {=IFERROR(INDEX('Log Diário'!$K$2:$K$156,SMALL(IF(('Log Diário'!$B$2:$B$156="Rogério Matos")*('Log Diário'!$A$2:$A$156=Painel!$B$4),ROW('Log Diário'!$A$2:$A$156)-1,""),9)),"")&""}
C39: {=IFERROR(INDEX('Log Diário'!$C$2:$C$156,SMALL(IF(('Log Diário'!$B$2:$B$156="Rogério Matos")*('Log Diário'!$A$2:$A$156=Painel!$B$4),ROW('Log Diário'!$A$2:$A$156)-1,""),10)),"")} | D39: {=IFERROR(INDEX('Log Diário'!$D$2:$D$156,SMALL(IF(('Log Diário'!$B$2:$B$156="Rogério Matos")*('Log Diário'!$A$2:$A$156=Painel!$B$4),ROW('Log Diário'!$A$2:$A$156)-1,""),10)),"")} | E39: {=IFERROR(INDEX('Log Diário'!$E$2:$E$156,SMALL(IF(('Log Diário'!$B$2:$B$156="Rogério Matos")*('Log Diário'!$A$2:$A$156=Painel!$B$4),ROW('Log Diário'!$A$2:$A$156)-1,""),10)),"")} | F39: {=IFERROR(INDEX('Log Diário'!$F$2:$F$156,SMALL(IF(('Log Diário'!$B$2:$B$156="Rogério Matos")*('Log Diário'!$A$2:$A$156=Painel!$B$4),ROW('Log Diário'!$A$2:$A$156)-1,""),10)),"")} | K39: {=IFERROR(INDEX('Log Diário'!$I$2:$I$156,SMALL(IF(('Log Diário'!$B$2:$B$156="Rogério Matos")*('Log Diário'!$A$2:$A$156=Painel!$B$4),ROW('Log Diário'!$A$2:$A$156)-1,""),10)),"")} | M39: {=IFERROR(INDEX('Log Diário'!$K$2:$K$156,SMALL(IF(('Log Diário'!$B$2:$B$156="Rogério Matos")*('Log Diário'!$A$2:$A$156=Painel!$B$4),ROW('Log Diário'!$A$2:$A$156)-1,""),10)),"")&""}
C41: =IF(COUNTIFS('Log Diário'!$B$2:$B$699,"Rogério Matos",'Log Diário'!$A$2:$A$699,Painel!$B$4)=0,"⚠ Nenhuma atividade registrada para "&TEXT(Painel!$B$4,"DD/MM/YYYY")&" — relatório diário pendente","")
C42: 💡 Para registrar novas atividades, adicione uma linha na aba "Log Diário" com a data correspondente.
C199: Status | D199: Qtd
C200: =IF(D200=0,"","Não iniciado") | D200: =COUNTIFS('Log Diário'!$B$2:$B$699,"Rogério Matos",'Log Diário'!$A$2:$A$699,Painel!$B$4,'Log Diário'!$I$2:$I$699,"Não iniciado") -> 0
C201: =IF(D201=0,"","Em andamento") -> Em andamento | D201: =COUNTIFS('Log Diário'!$B$2:$B$699,"Rogério Matos",'Log Diário'!$A$2:$A$699,Painel!$B$4,'Log Diário'!$I$2:$I$699,"Em andamento") -> 3
C202: =IF(D202=0,"","Acompanhamento") | D202: =COUNTIFS('Log Diário'!$B$2:$B$699,"Rogério Matos",'Log Diário'!$A$2:$A$699,Painel!$B$4,'Log Diário'!$I$2:$I$699,"Acompanhamento") -> 0
C203: =IF(D203=0,"","Inspecionado OK") | D203: =COUNTIFS('Log Diário'!$B$2:$B$699,"Rogério Matos",'Log Diário'!$A$2:$A$699,Painel!$B$4,'Log Diário'!$I$2:$I$699,"Inspecionado OK") -> 0
C204: =IF(D204=0,"","Pendência") | D204: =COUNTIFS('Log Diário'!$B$2:$B$699,"Rogério Matos",'Log Diário'!$A$2:$A$699,Painel!$B$4,'Log Diário'!$I$2:$I$699,"Pendência") -> 0
C205: =IF(D205=0,"","Reprovado") | D205: =COUNTIFS('Log Diário'!$B$2:$B$699,"Rogério Matos",'Log Diário'!$A$2:$A$699,Painel!$B$4,'Log Diário'!$I$2:$I$699,"Reprovado") -> 0

Sheet Marcos Antonio
C1: MARCOS ANTONIO
C2: Inspeção de Qualidade — Preservação
C3: 📅 Data de referência: | M3: =Painel!$B$4 -> 46203
C5: ATIVIDADES HOJE | G5: EM ANDAMENTO/ACOMP. HOJE | K5: PENDÊNCIAS HOJE
C6: =COUNTIFS('Log Diário'!$B$2:$B$699,"Marcos Antonio",'Log Diário'!$A$2:$A$699,Painel!$B$4) -> 2 | G6: =COUNTIFS('Log Diário'!$B$2:$B$699,"Marcos Antonio",'Log Diário'!$A$2:$A$699,Painel!$B$4,'Log Diário'!$I$2:$I$699,"Em andamento")+COUNTIFS('Log Diário'!$B$2:$B$699,"Marcos Antonio",'Log Diário'!$A$2:$A$699,Painel!$B$4,'Log Diário'!$I$2:$I$699,"Acompanhamento") -> 1 | K6: =COUNTIFS('Log Diário'!$B$2:$B$699,"Marcos Antonio",'Log Diário'!$A$2:$A$699,Painel!$B$4,'Log Diário'!$I$2:$I$699,"Pendência")+COUNTIFS('Log Diário'!$B$2:$B$699,"Marcos Antonio",'Log Diário'!$A$2:$A$699,Painel!$B$4,'Log Diário'!$I$2:$I$699,"Reprovado") -> 0
C10: ="📈 Total de atividades registradas em "&INDEX({"janeiro";"fevereiro";"março";"abril";"maio";"junho";"julho";"agosto";"setembro";"outubro";"novembro";"dezembro"},MONTH(Painel!$B$4))&"/"&YEAR(Painel!$B$4)&": "&COUNTIFS('Log Diário'!$B$2:$B$699,"Marcos Antonio",'Log Diário'!$A$2:$A$699,">"&DATE(YEAR(Painel!$B$4),MONTH(Painel!$B$4),1),'Log Diário'!$A$2:$A$699,"<"&DATE(YEAR(Painel!$B$4),MONTH(Painel!$B$4)+1,1))&" atividades" -> 📈 Total de atividades registradas em junho/2026: 14 atividades
H12: 📋 DISCIPLINAS ENVOLVIDAS HOJE
H13: =TRIM(IF(COUNTIFS('Log Diário'!$B$2:$B$699,"Marcos Antonio",'Log Diário'!$A$2:$A$699,Painel!$B$4,'Log Diário'!$C$2:$C$699,"ELE")>0,"ELE ","")&IF(COUNTIFS('Log Diário'!$B$2:$B$699,"Marcos Antonio",'Log Diário'!$A$2:$A$699,Painel!$B$4,'Log Diário'!$C$2:$C$699,"TUB")>0,"TUB ","")&IF(COUNTIFS('Log Diário'!$B$2:$B$699,"Marcos Antonio",'Log Diário'!$A$2:$A$699,Painel!$B$4,'Log Diário'!$C$2:$C$699,"MEC")>0,"MEC ","")&IF(COUNTIFS('Log Diário'!$B$2:$B$699,"Marcos Antonio",'Log Diário'!$A$2:$A$699,Painel!$B$4,'Log Diário'!$C$2:$C$699,"SOLDA")>0,"SOLDA ","")&IF(COUNTIFS('Log Diário'!$B$2:$B$699,"Marcos Antonio",'Log Diário'!$A$2:$A$699,Painel!$B$4,'Log Diário'!$C$2:$C$699,"AND")>0,"AND ","")&IF(COUNTIFS('Log Diário'!$B$2:$B$699,"Marcos Antonio",'Log Diário'!$A$2:$A$699,Painel!$B$4,'Log Diário'!$C$2:$C$699,"ADM")>0,"ADM ",""))
H15: 📍 ÁREAS / CWAs EM ACOMPANHAMENTO HOJE
H16: {=IF(RIGHT(IFERROR(INDEX('Log Diário'!$D$2:$D$699,SMALL(IF(('Log Diário'!$B$2:$B$699="Marcos Antonio")*('Log Diário'!$A$2:$A$699=Painel!$B$4),ROW('Log Diário'!$A$2:$A$699)-1,""),1))&" | ","")&IFERROR(INDEX('Log Diário'!$D$2:$D$699,SMALL(IF(('Log Diário'!$B$2:$B$699="Marcos Antonio")*('Log Diário'!$A$2:$A$699=Painel!$B$4),ROW('Log Diário'!$A$2:$A$699)-1,""),2))&" | ","")&IFERROR(INDEX('Log Diário'!$D$2:$D$699,SMALL(IF(('Log Diário'!$B$2:$B$699="Marcos Antonio")*('Log Diário'!$A$2:$A$699=Painel!$B$4),ROW('Log Diário'!$A$2:$A$699)-1,""),3))&" | ","")&IFERROR(INDEX('Log Diário'!$D$2:$D$699,SMALL(IF(('Log Diário'!$B$2:$B$699="Marcos Antonio")*('Log Diário'!$A$2:$A$699=Painel!$B$4),ROW('Log Diário'!$A$2:$A$699)-1,""),4))&" | ","")&IFERROR(INDEX('Log Diário'!$D$2:$D$699,SMALL(IF(('Log Diário'!$B$2:$B$699="Marcos Antonio")*('Log Diário'!$A$2:$A$699=Painel!$B$4),ROW('Log Diário'!$A$2:$A$699)-1,""),5))&" | ","")&IFERROR(INDEX('Log Diário'!$D$2:$D$699,SMALL(IF(('Log Diário'!$B$2:$B$699="Marcos Antonio")*('Log Diário'!$A$2:$A$699=Painel!$B$4),ROW('Log Diário'!$A$2:$A$699)-1,""),6))&" | ",""),7)=" | ",LEFT(IFERROR(INDEX('Log Diário'!$D$2:$D$699,SMALL(IF(('Log Diário'!$B$2:$B$699="Marcos Antonio")*('Log Diário'!$A$2:$A$699=Painel!$B$4),ROW('Log Diário'!$A$2:$A$699)-1,""),1))&" | ","")&IFERROR(INDEX('Log Diário'!$D$2:$D$699,SMALL(IF(('Log Diário'!$B$2:$B$699="Marcos Antonio")*('Log Diário'!$A$2:$A$699=Painel!$B$4),ROW('Log Diário'!$A$2:$A$699)-1,""),2))&" | ","")&IFERROR(INDEX('Log Diário'!$D$2:$D$699,SMALL(IF(('Log Diário'!$B$2:$B$699="Marcos Antonio")*('Log Diário'!$A$2:$A$699=Painel!$B$4),ROW('Log Diário'!$A$2:$A$699)-1,""),3))&" | ","")&IFERROR(INDEX('Log Diário'!$D$2:$D$699,SMALL(IF(('Log Diário'!$B$2:$B$699="Marcos Antonio")*('Log Diário'!$A$2:$A$699=Painel!$B$4),ROW('Log Diário'!$A$2:$A$699)-1,""),4))&" | ","")&IFERROR(INDEX('Log Diário'!$D$2:$D$699,SMALL(IF(('Log Diário'!$B$2:$B$699="Marcos Antonio")*('Log Diário'!$A$2:$A$699=Painel!$B$4),ROW('Log Diário'!$A$2:$A$699)-1,""),5))&" | ","")&IFERROR(INDEX('Log Diário'!$D$2:$D$699,SMALL(IF(('Log Diário'!$B$2:$B$699="Marcos Antonio")*('Log Diário'!$A$2:$A$699=Painel!$B$4),ROW('Log Diário'!$A$2:$A$699)-1,""),6))&" | ",""),LEN(IFERROR(INDEX('Log Diário'!$D$2:$D$699,SMALL(IF(('Log Diário'!$B$2:$B$699="Marcos Antonio")*('Log Diário'!$A$2:$A$699=Painel!$B$4),ROW('Log Diário'!$A$2:$A$699)-1,""),1))&" | ","")&IFERROR(INDEX('Log Diário'!$D$2:$D$699,SMALL(IF(('Log Diário'!$B$2:$B$699="Marcos Antonio")*('Log Diário'!$A$2:$A$699=Painel!$B$4),ROW('Log Diário'!$A$2:$A$699)-1,""),2))&" | ","")&IFERROR(INDEX('Log Diário'!$D$2:$D$699,SMALL(IF(('Log Diário'!$B$2:$B$699="Marcos Antonio")*('Log Diário'!$A$2:$A$699=Painel!$B$4),ROW('Log Diário'!$A$2:$A$699)-1,""),3))&" | ","")&IFERROR(INDEX('Log Diário'!$D$2:$D$699,SMALL(IF(('Log Diário'!$B$2:$B$699="Marcos Antonio")*('Log Diário'!$A$2:$A$699=Painel!$B$4),ROW('Log Diário'!$A$2:$A$699)-1,""),4))&" | ","")&IFERROR(INDEX('Log Diário'!$D$2:$D$699,SMALL(IF(('Log Diário'!$B$2:$B$699="Marcos Antonio")*('Log Diário'!$A$2:$A$699=Painel!$B$4),ROW('Log Diário'!$A$2:$A$699)-1,""),5))&" | ","")&IFERROR(INDEX('Log Diário'!$D$2:$D$699,SMALL(IF(('Log Diário'!$B$2:$B$699="Marcos Antonio")*('Log Diário'!$A$2:$A$699=Painel!$B$4),ROW('Log Diário'!$A$2:$A$699)-1,""),6))&" | ",""))-7),IFERROR(INDEX('Log Diário'!$D$2:$D$699,SMALL(IF(('Log Diário'!$B$2:$B$699="Marcos Antonio")*('Log Diário'!$A$2:$A$699=Painel!$B$4),ROW('Log Diário'!$A$2:$A$699)-1,""),1))&" | ","")&IFERROR(INDEX('Log Diário'!$D$2:$D$699,SMALL(IF(('Log Diário'!$B$2:$B$699="Marcos Antonio")*('Log Diário'!$A$2:$A$699=Painel!$B$4),ROW('Log Diário'!$A$2:$A$699)-1,""),2))&" | ","")&IFERROR(INDEX('Log Diário'!$D$2:$D$699,SMALL(IF(('Log Diário'!$B$2:$B$699="Marcos Antonio")*('Log Diário'!$A$2:$A$699=Painel!$B$4),ROW('Log Diário'!$A$2:$A$699)-1,""),3))&" | ","")&IFERROR(INDEX('Log Diário'!$D$2:$D$699,SMALL(IF(('Log Diário'!$B$2:$B$699="Marcos Antonio")*('Log Diário'!$A$2:$A$699=Painel!$B$4),ROW('Log Diário'!$A$2:$A$699)-1,""),4))&" | ","")&IFERROR(INDEX('Log Diário'!$D$2:$D$699,SMALL(IF(('Log Diário'!$B$2:$B$699="Marcos Antonio")*('Log Diário'!$A$2:$A$699=Painel!$B$4),ROW('Log Diário'!$A$2:$A$699)-1,""),5))&" | ","")&IFERROR(INDEX('Log Diário'!$D$2:$D$699,SMALL(IF(('Log Diário'!$B$2:$B$699="Marcos Antonio")*('Log Diário'!$A$2:$A$699=Painel!$B$4),ROW('Log Diário'!$A$2:$A$699)-1,""),6))&" | ",""))} -> Platô 16 | Platô 9A
C28: ="🗓️ ATIVIDADES DE HOJE — "&TEXT(Painel!$B$4,"DD/MM/YYYY") -> 🗓️ ATIVIDADES DE HOJE — 30/06/YYYY
C29: DISC. | D29: ÁREA | E29: SUPERVISOR | F29: ATIVIDADE | K29: STATUS | M29: ⚠️ OBSERVAÇÃO / CHECK-IN
C30: {=IFERROR(INDEX('Log Diário'!$C$2:$C$156,SMALL(IF(('Log Diário'!$B$2:$B$156="Marcos Antonio")*('Log Diário'!$A$2:$A$156=Painel!$B$4),ROW('Log Diário'!$A$2:$A$156)-1,""),1)),"")} -> MAT | D30: {=IFERROR(INDEX('Log Diário'!$D$2:$D$156,SMALL(IF(('Log Diário'!$B$2:$B$156="Marcos Antonio")*('Log Diário'!$A$2:$A$156=Painel!$B$4),ROW('Log Diário'!$A$2:$A$156)-1,""),1)),"")} -> Platô 16 | E30: {=IFERROR(INDEX('Log Diário'!$E$2:$E$156,SMALL(IF(('Log Diário'!$B$2:$B$156="Marcos Antonio")*('Log Diário'!$A$2:$A$156=Painel!$B$4),ROW('Log Diário'!$A$2:$A$156)-1,""),1)),"")} -> Arlem | F30: {=IFERROR(INDEX('Log Diário'!$F$2:$F$156,SMALL(IF(('Log Diário'!$B$2:$B$156="Marcos Antonio")*('Log Diário'!$A$2:$A$156=Painel!$B$4),ROW('Log Diário'!$A$2:$A$156)-1,""),1)),"")} -> Recebimento de parafusos | K30: {=IFERROR(INDEX('Log Diário'!$I$2:$I$156,SMALL(IF(('Log Diário'!$B$2:$B$156="Marcos Antonio")*('Log Diário'!$A$2:$A$156=Painel!$B$4),ROW('Log Diário'!$A$2:$A$156)-1,""),1)),"")} -> Encerrado | M30: {=IFERROR(INDEX('Log Diário'!$K$2:$K$156,SMALL(IF(('Log Diário'!$B$2:$B$156="Marcos Antonio")*('Log Diário'!$A$2:$A$156=Painel!$B$4),ROW('Log Diário'!$A$2:$A$156)-1,""),1)),"")&""}
C31: {=IFERROR(INDEX('Log Diário'!$C$2:$C$156,SMALL(IF(('Log Diário'!$B$2:$B$156="Marcos Antonio")*('Log Diário'!$A$2:$A$156=Painel!$B$4),ROW('Log Diário'!$A$2:$A$156)-1,""),2)),"")} -> MAT | D31: {=IFERROR(INDEX('Log Diário'!$D$2:$D$156,SMALL(IF(('Log Diário'!$B$2:$B$156="Marcos Antonio")*('Log Diário'!$A$2:$A$156=Painel!$B$4),ROW('Log Diário'!$A$2:$A$156)-1,""),2)),"")} -> Platô 9A | E31: {=IFERROR(INDEX('Log Diário'!$E$2:$E$156,SMALL(IF(('Log Diário'!$B$2:$B$156="Marcos Antonio")*('Log Diário'!$A$2:$A$156=Painel!$B$4),ROW('Log Diário'!$A$2:$A$156)-1,""),2)),"")} -> Leonildo | F31: {=IFERROR(INDEX('Log Diário'!$F$2:$F$156,SMALL(IF(('Log Diário'!$B$2:$B$156="Marcos Antonio")*('Log Diário'!$A$2:$A$156=Painel!$B$4),ROW('Log Diário'!$A$2:$A$156)-1,""),2)),"")} -> Preservação — Colunas de Flotação | K31: {=IFERROR(INDEX('Log Diário'!$I$2:$I$156,SMALL(IF(('Log Diário'!$B$2:$B$156="Marcos Antonio")*('Log Diário'!$A$2:$A$156=Painel!$B$4),ROW('Log Diário'!$A$2:$A$156)-1,""),2)),"")} -> Em andamento | M31: {=IFERROR(INDEX('Log Diário'!$K$2:$K$156,SMALL(IF(('Log Diário'!$B$2:$B$156="Marcos Antonio")*('Log Diário'!$A$2:$A$156=Painel!$B$4),ROW('Log Diário'!$A$2:$A$156)-1,""),2)),"")&""}
C32: {=IFERROR(INDEX('Log Diário'!$C$2:$C$156,SMALL(IF(('Log Diário'!$B$2:$B$156="Marcos Antonio")*('Log Diário'!$A$2:$A$156=Painel!$B$4),ROW('Log Diário'!$A$2:$A$156)-1,""),3)),"")} | D32: {=IFERROR(INDEX('Log Diário'!$D$2:$D$156,SMALL(IF(('Log Diário'!$B$2:$B$156="Marcos Antonio")*('Log Diário'!$A$2:$A$156=Painel!$B$4),ROW('Log Diário'!$A$2:$A$156)-1,""),3)),"")} | E32: {=IFERROR(INDEX('Log Diário'!$E$2:$E$156,SMALL(IF(('Log Diário'!$B$2:$B$156="Marcos Antonio")*('Log Diário'!$A$2:$A$156=Painel!$B$4),ROW('Log Diário'!$A$2:$A$156)-1,""),3)),"")} | F32: {=IFERROR(INDEX('Log Diário'!$F$2:$F$156,SMALL(IF(('Log Diário'!$B$2:$B$156="Marcos Antonio")*('Log Diário'!$A$2:$A$156=Painel!$B$4),ROW('Log Diário'!$A$2:$A$156)-1,""),3)),"")} | K32: {=IFERROR(INDEX('Log Diário'!$I$2:$I$156,SMALL(IF(('Log Diário'!$B$2:$B$156="Marcos Antonio")*('Log Diário'!$A$2:$A$156=Painel!$B$4),ROW('Log Diário'!$A$2:$A$156)-1,""),3)),"")} | M32: {=IFERROR(INDEX('Log Diário'!$K$2:$K$156,SMALL(IF(('Log Diário'!$B$2:$B$156="Marcos Antonio")*('Log Diário'!$A$2:$A$156=Painel!$B$4),ROW('Log Diário'!$A$2:$A$156)-1,""),3)),"")&""}
C33: {=IFERROR(INDEX('Log Diário'!$C$2:$C$156,SMALL(IF(('Log Diário'!$B$2:$B$156="Marcos Antonio")*('Log Diário'!$A$2:$A$156=Painel!$B$4),ROW('Log Diário'!$A$2:$A$156)-1,""),4)),"")} | D33: {=IFERROR(INDEX('Log Diário'!$D$2:$D$156,SMALL(IF(('Log Diário'!$B$2:$B$156="Marcos Antonio")*('Log Diário'!$A$2:$A$156=Painel!$B$4),ROW('Log Diário'!$A$2:$A$156)-1,""),4)),"")} | E33: {=IFERROR(INDEX('Log Diário'!$E$2:$E$156,SMALL(IF(('Log Diário'!$B$2:$B$156="Marcos Antonio")*('Log Diário'!$A$2:$A$156=Painel!$B$4),ROW('Log Diário'!$A$2:$A$156)-1,""),4)),"")} | F33: {=IFERROR(INDEX('Log Diário'!$F$2:$F$156,SMALL(IF(('Log Diário'!$B$2:$B$156="Marcos Antonio")*('Log Diário'!$A$2:$A$156=Painel!$B$4),ROW('Log Diário'!$A$2:$A$156)-1,""),4)),"")} | K33: {=IFERROR(INDEX('Log Diário'!$I$2:$I$156,SMALL(IF(('Log Diário'!$B$2:$B$156="Marcos Antonio")*('Log Diário'!$A$2:$A$156=Painel!$B$4),ROW('Log Diário'!$A$2:$A$156)-1,""),4)),"")} | M33: {=IFERROR(INDEX('Log Diário'!$K$2:$K$156,SMALL(IF(('Log Diário'!$B$2:$B$156="Marcos Antonio")*('Log Diário'!$A$2:$A$156=Painel!$B$4),ROW('Log Diário'!$A$2:$A$156)-1,""),4)),"")&""}
C34: {=IFERROR(INDEX('Log Diário'!$C$2:$C$156,SMALL(IF(('Log Diário'!$B$2:$B$156="Marcos Antonio")*('Log Diário'!$A$2:$A$156=Painel!$B$4),ROW('Log Diário'!$A$2:$A$156)-1,""),5)),"")} | D34: {=IFERROR(INDEX('Log Diário'!$D$2:$D$156,SMALL(IF(('Log Diário'!$B$2:$B$156="Marcos Antonio")*('Log Diário'!$A$2:$A$156=Painel!$B$4),ROW('Log Diário'!$A$2:$A$156)-1,""),5)),"")} | E34: {=IFERROR(INDEX('Log Diário'!$E$2:$E$156,SMALL(IF(('Log Diário'!$B$2:$B$156="Marcos Antonio")*('Log Diário'!$A$2:$A$156=Painel!$B$4),ROW('Log Diário'!$A$2:$A$156)-1,""),5)),"")} | F34: {=IFERROR(INDEX('Log Diário'!$F$2:$F$156,SMALL(IF(('Log Diário'!$B$2:$B$156="Marcos Antonio")*('Log Diário'!$A$2:$A$156=Painel!$B$4),ROW('Log Diário'!$A$2:$A$156)-1,""),5)),"")} | K34: {=IFERROR(INDEX('Log Diário'!$I$2:$I$156,SMALL(IF(('Log Diário'!$B$2:$B$156="Marcos Antonio")*('Log Diário'!$A$2:$A$156=Painel!$B$4),ROW('Log Diário'!$A$2:$A$156)-1,""),5)),"")} | M34: {=IFERROR(INDEX('Log Diário'!$K$2:$K$156,SMALL(IF(('Log Diário'!$B$2:$B$156="Marcos Antonio")*('Log Diário'!$A$2:$A$156=Painel!$B$4),ROW('Log Diário'!$A$2:$A$156)-1,""),5)),"")&""}
C35: {=IFERROR(INDEX('Log Diário'!$C$2:$C$156,SMALL(IF(('Log Diário'!$B$2:$B$156="Marcos Antonio")*('Log Diário'!$A$2:$A$156=Painel!$B$4),ROW('Log Diário'!$A$2:$A$156)-1,""),6)),"")} | D35: {=IFERROR(INDEX('Log Diário'!$D$2:$D$156,SMALL(IF(('Log Diário'!$B$2:$B$156="Marcos Antonio")*('Log Diário'!$A$2:$A$156=Painel!$B$4),ROW('Log Diário'!$A$2:$A$156)-1,""),6)),"")} | E35: {=IFERROR(INDEX('Log Diário'!$E$2:$E$156,SMALL(IF(('Log Diário'!$B$2:$B$156="Marcos Antonio")*('Log Diário'!$A$2:$A$156=Painel!$B$4),ROW('Log Diário'!$A$2:$A$156)-1,""),6)),"")} | F35: {=IFERROR(INDEX('Log Diário'!$F$2:$F$156,SMALL(IF(('Log Diário'!$B$2:$B$156="Marcos Antonio")*('Log Diário'!$A$2:$A$156=Painel!$B$4),ROW('Log Diário'!$A$2:$A$156)-1,""),6)),"")} | K35: {=IFERROR(INDEX('Log Diário'!$I$2:$I$156,SMALL(IF(('Log Diário'!$B$2:$B$156="Marcos Antonio")*('Log Diário'!$A$2:$A$156=Painel!$B$4),ROW('Log Diário'!$A$2:$A$156)-1,""),6)),"")} | M35: {=IFERROR(INDEX('Log Diário'!$K$2:$K$156,SMALL(IF(('Log Diário'!$B$2:$B$156="Marcos Antonio")*('Log Diário'!$A$2:$A$156=Painel!$B$4),ROW('Log Diário'!$A$2:$A$156)-1,""),6)),"")&""}
C36: {=IFERROR(INDEX('Log Diário'!$C$2:$C$156,SMALL(IF(('Log Diário'!$B$2:$B$156="Marcos Antonio")*('Log Diário'!$A$2:$A$156=Painel!$B$4),ROW('Log Diário'!$A$2:$A$156)-1,""),7)),"")} | D36: {=IFERROR(INDEX('Log Diário'!$D$2:$D$156,SMALL(IF(('Log Diário'!$B$2:$B$156="Marcos Antonio")*('Log Diário'!$A$2:$A$156=Painel!$B$4),ROW('Log Diário'!$A$2:$A$156)-1,""),7)),"")} | E36: {=IFERROR(INDEX('Log Diário'!$E$2:$E$156,SMALL(IF(('Log Diário'!$B$2:$B$156="Marcos Antonio")*('Log Diário'!$A$2:$A$156=Painel!$B$4),ROW('Log Diário'!$A$2:$A$156)-1,""),7)),"")} | F36: {=IFERROR(INDEX('Log Diário'!$F$2:$F$156,SMALL(IF(('Log Diário'!$B$2:$B$156="Marcos Antonio")*('Log Diário'!$A$2:$A$156=Painel!$B$4),ROW('Log Diário'!$A$2:$A$156)-1,""),7)),"")} | K36: {=IFERROR(INDEX('Log Diário'!$I$2:$I$156,SMALL(IF(('Log Diário'!$B$2:$B$156="Marcos Antonio")*('Log Diário'!$A$2:$A$156=Painel!$B$4),ROW('Log Diário'!$A$2:$A$156)-1,""),7)),"")} | M36: {=IFERROR(INDEX('Log Diário'!$K$2:$K$156,SMALL(IF(('Log Diário'!$B$2:$B$156="Marcos Antonio")*('Log Diário'!$A$2:$A$156=Painel!$B$4),ROW('Log Diário'!$A$2:$A$156)-1,""),7)),"")&""}
